2018-03-28 12:30:19,353 ERROR: Exception on /index [GET] [in c:\users\bencw\anaconda3\envs\goodbyefriendship\lib\site-packages\flask\app.py:1560]
Traceback (most recent call last):
  File "c:\users\bencw\anaconda3\envs\goodbyefriendship\lib\site-packages\flask\app.py", line 1982, in wsgi_app
    response = self.full_dispatch_request()
  File "c:\users\bencw\anaconda3\envs\goodbyefriendship\lib\site-packages\flask\app.py", line 1614, in full_dispatch_request
    rv = self.handle_user_exception(e)
  File "c:\users\bencw\anaconda3\envs\goodbyefriendship\lib\site-packages\flask\app.py", line 1517, in handle_user_exception
    reraise(exc_type, exc_value, tb)
  File "c:\users\bencw\anaconda3\envs\goodbyefriendship\lib\site-packages\flask\_compat.py", line 33, in reraise
    raise value
  File "c:\users\bencw\anaconda3\envs\goodbyefriendship\lib\site-packages\flask\app.py", line 1612, in full_dispatch_request
    rv = self.dispatch_request()
  File "c:\users\bencw\anaconda3\envs\goodbyefriendship\lib\site-packages\flask\app.py", line 1598, in dispatch_request
    return self.view_functions[rule.endpoint](**req.view_args)
  File "c:\users\bencw\anaconda3\envs\goodbyefriendship\lib\site-packages\flask_login\utils.py", line 261, in decorated_view
    return func(*args, **kwargs)
  File "C:\Users\bencw\Documents\GitHub\GoodbyeFriendship\app\routes.py", line 27, in index
    return render_template('index.html', title='home', form=form, posts=posts )
  File "c:\users\bencw\anaconda3\envs\goodbyefriendship\lib\site-packages\flask\templating.py", line 134, in render_template
    context, ctx.app)
  File "c:\users\bencw\anaconda3\envs\goodbyefriendship\lib\site-packages\flask\templating.py", line 116, in _render
    rv = template.render(context)
  File "c:\users\bencw\anaconda3\envs\goodbyefriendship\lib\site-packages\jinja2\asyncsupport.py", line 76, in render
    return original_render(self, *args, **kwargs)
  File "c:\users\bencw\anaconda3\envs\goodbyefriendship\lib\site-packages\jinja2\environment.py", line 1008, in render
    return self.environment.handle_exception(exc_info, True)
  File "c:\users\bencw\anaconda3\envs\goodbyefriendship\lib\site-packages\jinja2\environment.py", line 780, in handle_exception
    reraise(exc_type, exc_value, tb)
  File "c:\users\bencw\anaconda3\envs\goodbyefriendship\lib\site-packages\jinja2\_compat.py", line 37, in reraise
    raise value.with_traceback(tb)
  File "C:\Users\bencw\Documents\GitHub\GoodbyeFriendship\app\templates\index.html", line 1, in top-level template code
    {% extends "base.html" %}
  File "C:\Users\bencw\Documents\GitHub\GoodbyeFriendship\app\templates\base.html", line 30, in top-level template code
    {% block content %}{% endblock %}
  File "C:\Users\bencw\Documents\GitHub\GoodbyeFriendship\app\templates\index.html", line 19, in block "content"
    {% include '_post.html' %}
  File "C:\Users\bencw\Documents\GitHub\GoodbyeFriendship\app\templates\_post.html", line 3, in top-level template code
    <td><img src="{{ user.avatar(36) }}"></td>
  File "c:\users\bencw\anaconda3\envs\goodbyefriendship\lib\site-packages\jinja2\environment.py", line 430, in getattr
    return getattr(obj, attribute)
jinja2.exceptions.UndefinedError: 'user' is undefined
